Traceback (most recent call last):
  File "main.py", line 29, in <module>
    main()
  File "main.py", line 25, in main
    manager.run()
  File "/home/kostas/.pyenv/versions/flask_api_petstore_project/lib/python3.7/site-packages/flask_script/__init__.py", line 412, in run
    result = self.handle(sys.argv[0], sys.argv[1:])
  File "/home/kostas/.pyenv/versions/flask_api_petstore_project/lib/python3.7/site-packages/flask_script/__init__.py", line 383, in handle
    res = handle(*args, **config)
  File "/home/kostas/.pyenv/versions/flask_api_petstore_project/lib/python3.7/site-packages/flask_script/commands.py", line 425, in __call__
    **self.server_options)
  File "/home/kostas/.pyenv/versions/flask_api_petstore_project/lib/python3.7/site-packages/flask/app.py", line 843, in run
    run_simple(host, port, self, **options)
  File "/home/kostas/.pyenv/versions/flask_api_petstore_project/lib/python3.7/site-packages/werkzeug/serving.py", line 984, in run_simple
    s.bind(server_address)
OSError: [Errno 98] Address already in use
 * Running on all addresses.
   WARNING: This is a development server. Do not use it in a production deployment.
 * Running on http://192.168.1.6:8000/ (Press CTRL+C to quit)
 * Restarting with stat
 * Debugger is active!
 * Debugger PIN: 697-696-664
127.0.0.1 - - [05/Dec/2021 14:05:36] "GET / HTTP/1.1" 200 -
 * Running on all addresses.
   WARNING: This is a development server. Do not use it in a production deployment.
 * Running on http://192.168.1.6:8000/ (Press CTRL+C to quit)
 * Restarting with stat
 * Debugger is active!
 * Debugger PIN: 697-696-664
 * Running on all addresses.
   WARNING: This is a development server. Do not use it in a production deployment.
 * Running on http://192.168.1.6:8000/ (Press CTRL+C to quit)
 * Restarting with stat
 * Debugger is active!
 * Debugger PIN: 697-696-664
127.0.0.1 - - [05/Dec/2021 14:08:00] "GET / HTTP/1.1" 200 -
 * Running on all addresses.
   WARNING: This is a development server. Do not use it in a production deployment.
 * Running on http://192.168.1.6:8000/ (Press CTRL+C to quit)
 * Restarting with stat
 * Debugger is active!
 * Debugger PIN: 697-696-664
127.0.0.1 - - [05/Dec/2021 14:08:28] "GET / HTTP/1.1" 200 -
127.0.0.1 - - [05/Dec/2021 14:09:05] "GET / HTTP/1.1" 200 -
petstore - ERROR - Loading configuration file failed due to: 'CONFIG_FOLDER_NAME'
Traceback (most recent call last):
  File "main.py", line 29, in <module>
    main()
  File "main.py", line 11, in main
    app = petstore.create_app()
  File "/home/kostas/Desktop/PythonGeneral/practise-flask-rest-api-pet-store/petstore.py", line 30, in create_app
    raise exc
  File "/home/kostas/Desktop/PythonGeneral/practise-flask-rest-api-pet-store/petstore.py", line 27, in create_app
    self.config_service.load()
  File "/home/kostas/Desktop/PythonGeneral/practise-flask-rest-api-pet-store/core/config_service.py", line 21, in load
    self.config_folder_name = os.environ["CONFIG_FOLDER_NAME"]
  File "/home/kostas/.pyenv/versions/3.7.4/lib/python3.7/os.py", line 678, in __getitem__
    raise KeyError(key) from None
KeyError: 'CONFIG_FOLDER_NAME'
